Workbook

Sheet grade_analysis_gender_ethnicity
A2: Diversity of Gender and Ethincity by Grade
A3: Count of grade | B3: Column Labels | U3: Count of grade | V3: Column Labels
A4: Row Labels | B4: G3 | C4: G4 | D4: G5 | E4: G6 | F4: G7 | G4: G8 | H4: G9 | I4: Grand Total | U4: Row Labels | V4: G3 | W4: G4 | X4: G5 | Y4: G6 | Z4: G7 | AA4: G8 | AB4: G9 | AC4: Grand Total
A5: Female | B5: 346 | C5: 637 | D5: 801 | E5: 561 | F5: 356 | G5: 177 | H5: 53 | I5: 2931 | U5: Asian | V5: 76 | W5: 155 | X5: 177 | Y5: 169 | Z5: 101 | AA5: 56 | AB5: 23 | AC5: 757
A6: Commercial Services | B6: 20 | C6: 37 | D6: 43 | E6: 27 | F6: 20 | G6: 4 | H6: 2 | I6: 153 | U6: Commercial Services | V6: 2 | W6: 10 | X6: 12 | Y6: 4 | Z6: 7 | AA6: 2 | AB6: 1 | AC6: 38
A7: Communications | B7: 47 | C7: 95 | D7: 122 | E7: 94 | F7: 54 | G7: 26 | H7: 10 | I7: 448 | U7: Communications | V7: 15 | W7: 28 | X7: 24 | Y7: 20 | Z7: 13 | AA7: 7 | AB7: 2 | AC7: 109
A8: Customer Services | B8: 27 | C8: 47 | D8: 60 | E8: 43 | F8: 31 | G8: 11 | H8: 3 | I8: 222 | U8: Customer Services | V8: 4 | W8: 13 | X8: 8 | Y8: 14 | Z8: 9 | AA8: 3 | AC8: 51
A9: Estates | B9: 26 | C9: 58 | D9: 53 | E9: 42 | F9: 24 | G9: 12 | H9: 8 | I9: 223 | U9: Estates | V9: 3 | W9: 12 | X9: 14 | Y9: 15 | Z9: 9 | AA9: 8 | AB9: 5 | AC9: 66
A10: Facilities | B10: 10 | C10: 32 | D10: 48 | E10: 29 | F10: 20 | G10: 11 | H10: 1 | I10: 151 | U10: Facilities | W10: 6 | X10: 6 | Y10: 7 | Z10: 4 | AA10: 3 | AC10: 26
A11: Finance | B11: 29 | C11: 42 | D11: 53 | E11: 35 | F11: 24 | G11: 13 | H11: 3 | I11: 199 | U11: Finance | V11: 7 | W11: 12 | X11: 17 | Y11: 10 | Z11: 3 | AA11: 8 | AB11: 1 | AC11: 58
A12: HR | B12: 36 | C12: 60 | D12: 62 | E12: 51 | F12: 35 | G12: 19 | H12: 2 | I12: 265 | U12: HR | V12: 4 | W12: 7 | X12: 12 | Y12: 14 | Z12: 12 | AA12: 4 | AC12: 53
A13: IT Services | B13: 27 | C13: 30 | D13: 50 | E13: 50 | F13: 24 | G13: 14 | H13: 2 | I13: 197 | U13: IT Services | V13: 4 | W13: 16 | X13: 11 | Y13: 13 | Z13: 11 | AA13: 3 | AB13: 1 | AC13: 59
A14: Legal and Governance | B14: 25 | C14: 40 | D14: 44 | E14: 30 | F14: 22 | G14: 14 | H14: 7 | I14: 182 | U14: Legal and Governance | V14: 10 | W14: 12 | X14: 7 | Y14: 14 | Z14: 9 | AA14: 2 | AB14: 1 | AC14: 55
A15: Marketing | B15: 20 | C15: 30 | D15: 52 | E15: 25 | F15: 13 | G15: 11 | H15: 4 | I15: 155 | U15: Marketing | V15: 7 | W15: 5 | X15: 7 | Y15: 9 | Z15: 2 | AA15: 3 | AB15: 5 | AC15: 38
A16: Planning | B16: 13 | C16: 26 | D16: 37 | E16: 23 | F16: 19 | G16: 7 | H16: 1 | I16: 126 | U16: Planning | V16: 2 | W16: 6 | X16: 12 | Y16: 11 | Z16: 3 | AC16: 34
A17: Procurement | B17: 8 | C17: 26 | D17: 28 | E17: 21 | F17: 12 | G17: 2 | I17: 97 | U17: Procurement | V17: 2 | W17: 5 | X17: 3 | Y17: 10 | Z17: 3 | AA17: 3 | AB17: 1 | AC17: 27
A18: Research and Development | B18: 18 | C18: 35 | D18: 52 | E18: 26 | F18: 20 | G18: 9 | H18: 2 | I18: 162 | U18: Research and Development | V18: 2 | W18: 7 | X18: 16 | Y18: 6 | Z18: 3 | AA18: 3 | AB18: 4 | AC18: 41
A19: Sales | B19: 37 | C19: 73 | D19: 86 | E19: 55 | F19: 32 | G19: 22 | H19: 7 | I19: 312 | U19: Sales | V19: 13 | W19: 13 | X19: 24 | Y19: 14 | Z19: 10 | AA19: 5 | AB19: 2 | AC19: 81
A20: Security | B20: 3 | C20: 6 | D20: 11 | E20: 10 | F20: 6 | G20: 2 | H20: 1 | I20: 39 | U20: Security | V20: 1 | W20: 3 | X20: 4 | Y20: 8 | Z20: 3 | AA20: 2 | AC20: 21
A21: Male | B21: 232 | C21: 445 | D21: 668 | E21: 712 | F21: 476 | G21: 285 | H21: 121 | I21: 2939 | U21: Black | V21: 35 | W21: 73 | X21: 105 | Y21: 80 | Z21: 39 | AA21: 32 | AB21: 12 | AC21: 376
A22: Commercial Services | B22: 8 | C22: 18 | D22: 39 | E22: 43 | F22: 21 | G22: 16 | H22: 5 | I22: 150 | U22: Commercial Services | V22: 1 | W22: 5 | X22: 10 | Y22: 6 | Z22: 2 | AA22: 3 | AC22: 27
A23: Communications | B23: 35 | C23: 55 | D23: 98 | E23: 79 | F23: 66 | G23: 23 | H23: 16 | I23: 372 | U23: Communications | V23: 4 | W23: 10 | X23: 16 | Y23: 11 | Z23: 7 | AA23: 4 | AB23: 2 | AC23: 54
A24: Customer Services | B24: 11 | C24: 33 | D24: 39 | E24: 54 | F24: 30 | G24: 23 | H24: 7 | I24: 197 | U24: Customer Services | V24: 3 | W24: 2 | X24: 6 | Y24: 8 | Z24: 1 | AA24: 2 | AB24: 1 | AC24: 23
A25: Estates | B25: 17 | C25: 38 | D25: 69 | E25: 62 | F25: 42 | G25: 24 | H25: 14 | I25: 266 | U25: Estates | V25: 4 | W25: 3 | X25: 9 | Y25: 10 | Z25: 3 | AA25: 1 | AB25: 1 | AC25: 31
A26: Facilities | B26: 10 | C26: 18 | D26: 35 | E26: 35 | F26: 22 | G26: 16 | H26: 7 | I26: 143 | U26: Facilities | V26: 4 | W26: 4 | X26: 3 | Z26: 2 | AB26: 1 | AC26: 14
A27: Finance | B27: 8 | C27: 27 | D27: 39 | E27: 42 | F27: 32 | G27: 19 | H27: 6 | I27: 173 | U27: Finance | W27: 6 | X27: 6 | Y27: 4 | Z27: 1 | AA27: 2 | AB27: 1 | AC27: 20
A28: HR | B28: 16 | C28: 26 | D28: 30 | E28: 31 | F28: 30 | G28: 8 | H28: 5 | I28: 146 | U28: HR | V28: 6 | W28: 3 | X28: 5 | Y28: 3 | Z28: 2 | AA28: 2 | AB28: 1 | AC28: 22
A29: IT Services | B29: 31 | C29: 64 | D29: 77 | E29: 83 | F29: 59 | G29: 36 | H29: 10 | I29: 360 | U29: IT Services | V29: 2 | W29: 8 | X29: 13 | Y29: 7 | Z29: 5 | AA29: 5 | AB29: 1 | AC29: 41
A30: Legal and Governance | B30: 14 | C30: 23 | D30: 36 | E30: 51 | F30: 38 | G30: 11 | H30: 6 | I30: 179 | U30: Legal and Governance | W30: 4 | X30: 3 | Y30: 6 | Z30: 5 | AA30: 1 | AC30: 19
A31: Marketing | B31: 10 | C31: 16 | D31: 25 | E31: 38 | F31: 20 | G31: 13 | H31: 5 | I31: 127 | U31: Marketing | V31: 2 | W31: 5 | X31: 8 | Y31: 4 | Z31: 2 | AA31: 1 | AC31: 22
A32: Planning | B32: 17 | C32: 17 | D32: 29 | E32: 39 | F32: 17 | G32: 18 | H32: 4 | I32: 141 | U32: Planning | W32: 4 | X32: 8 | Y32: 4 | Z32: 2 | AA32: 2 | AC32: 20
A33: Procurement | B33: 7 | C33: 20 | D33: 23 | E33: 29 | F33: 16 | G33: 16 | H33: 6 | I33: 117 | U33: Procurement | W33: 1 | X33: 3 | Y33: 2 | Z33: 2 | AA33: 3 | AC33: 11
A34: Research and Development | B34: 8 | C34: 15 | D34: 29 | E34: 21 | F34: 23 | G34: 19 | H34: 5 | I34: 120 | U34: Research and Development | V34: 3 | W34: 2 | X34: 7 | Y34: 4 | Z34: 2 | AA34: 1 | AB34: 1 | AC34: 20
A35: Sales | B35: 29 | C35: 48 | D35: 71 | E35: 63 | F35: 42 | G35: 34 | H35: 17 | I35: 304 | U35: Sales | V35: 6 | W35: 10 | X35: 6 | Y35: 6 | Z35: 2 | AA35: 4 | AB35: 3 | AC35: 37
A36: Security | B36: 11 | C36: 27 | D36: 29 | E36: 42 | F36: 18 | G36: 9 | H36: 8 | I36: 144 | U36: Security | W36: 6 | X36: 2 | Y36: 5 | Z36: 1 | AA36: 1 | AC36: 15
A37: Other | B37: 16 | C37: 30 | D37: 36 | E37: 24 | F37: 16 | G37: 6 | H37: 2 | I37: 130 | U37: Mixed | V37: 23 | W37: 49 | X37: 80 | Y37: 71 | Z37: 54 | AA37: 26 | AB37: 4 | AC37: 307
A38: Commercial Services | B38: 1 | C38: 1 | D38: 1 | E38: 1 | F38: 2 | I38: 6 | U38: Commercial Services | V38: 1 | X38: 5 | Y38: 5 | AB38: 1 | AC38: 12
A39: Communications | B39: 1 | C39: 4 | D39: 1 | E39: 5 | F39: 4 | I39: 15 | U39: Communications | V39: 5 | W39: 5 | X39: 7 | Y39: 10 | Z39: 9 | AA39: 5 | AB39: 1 | AC39: 42
A40: Customer Services | B40: 1 | C40: 1 | D40: 6 | E40: 1 | F40: 1 | I40: 10 | U40: Customer Services | W40: 7 | X40: 7 | Y40: 3 | Z40: 6 | AA40: 1 | AC40: 24
A41: Estates | B41: 2 | D41: 3 | E41: 1 | F41: 2 | G41: 1 | I41: 9 | U41: Estates | V41: 1 | W41: 3 | X41: 8 | Y41: 5 | Z41: 2 | AA41: 5 | AC41: 24
...

Sheet diversity_gender
A3: Count of staff_id | B3: Column Labels
A4: Row Labels | B4: Female | C4: Male | D4: Other | E4: Grand Total
A5: Commercial Services | B5: 153 | C5: 150 | D5: 6 | E5: 309
A6: Communications | B6: 448 | C6: 372 | D6: 15 | E6: 835
A7: Customer Services | B7: 222 | C7: 197 | D7: 10 | E7: 429
A8: Estates | B8: 223 | C8: 266 | D8: 9 | E8: 498
A9: Facilities | B9: 151 | C9: 143 | D9: 8 | E9: 302
A10: Finance | B10: 199 | C10: 173 | D10: 13 | E10: 385
A11: HR | B11: 265 | C11: 146 | D11: 4 | E11: 415
A12: IT Services | B12: 197 | C12: 360 | D12: 17 | E12: 574
A13: Legal and Governance | B13: 182 | C13: 179 | D13: 8 | E13: 369
A14: Marketing | B14: 155 | C14: 127 | D14: 8 | E14: 290
A15: Planning | B15: 126 | C15: 141 | D15: 5 | E15: 272
A16: Procurement | B16: 97 | C16: 117 | D16: 3 | E16: 217
... A20: Grand Total | B20: 2931 | C20: 2939 | D20: 130 | E20: 6000

Sheet diversity_ethnicity
A3: Count of staff_id | B3: Column Labels | J3: Count of staff_id | K3: Column Labels
A4: Row Labels | B4: Asian | C4: Black | D4: Mixed | E4: Other | F4: White | G4: Grand Total | J4: Row Labels | K4: Asian | L4: Black | M4: Mixed | N4: Other | O4: White | P4: Grand Total
A5: Commercial Services | B5: 38 | C5: 27 | D5: 12 | E5: 6 | F5: 226 | G5: 309 | J5: IT Services | K5: 59 | L5: 41 | M5: 29 | N5: 20 | O5: 425 | P5: 574
A6: Communications | B6: 109 | C6: 54 | D6: 42 | E6: 33 | F6: 597 | G6: 835 | J6: Grand Total | K6: 59 | L6: 41 | M6: 29 | N6: 20 | O6: 425 | P6: 574
A7: Customer Services | B7: 51 | C7: 23 | D7: 24 | E7: 18 | F7: 313 | G7: 429
A8: Estates | B8: 66 | C8: 31 | D8: 24 | E8: 18 | F8: 359 | G8: 498
A9: Facilities | B9: 26 | C9: 14 | D9: 24 | E9: 14 | F9: 224 | G9: 302
A10: Finance | B10: 58 | C10: 20 | D10: 22 | E10: 14 | F10: 271 | G10: 385
A11: HR | B11: 53 | C11: 22 | D11: 14 | E11: 9 | F11: 317 | G11: 415
A12: IT Services | B12: 59 | C12: 41 | D12: 29 | E12: 20 | F12: 425 | G12: 574
A13: Legal and Governance | B13: 55 | C13: 19 | D13: 21 | E13: 20 | F13: 254 | G13: 369
A14: Marketing | B14: 38 | C14: 22 | D14: 15 | E14: 7 | F14: 208 | G14: 290
A15: Planning | B15: 34 | C15: 20 | D15: 12 | E15: 9 | F15: 197 | G15: 272
A16: Procurement | B16: 27 | C16: 11 | D16: 16 | E16: 12 | F16: 151 | G16: 217
A17: Research and Development | B17: 41 | C17: 20 | D17: 10 | E17: 16 | F17: 203 | G17: 290
A18: Sales | B18: 81 | C18: 37 | D18: 35 | E18: 19 | F18: 456 | G18: 628
... A20: Grand Total | B20: 757 | C20: 376 | D20: 307 | E20: 222 | F20: 4338 | G20: 6000

Sheet diversity_total_org_pay
A1: Total Pay by Gender | G1: Total Pay by Ethincity
A2: Row Labels | B2: Sum of salary | G2: Row Labels | H2: Sum of salary
A3: Female | B3: 110217000 | G3: Asian | H3: 29634000
A4: Male | B4: 121465500 | G4: Black | H4: 14678000
A5: Other | B5: 4803000 | G5: Mixed | H5: 12305500
A6: Grand Total | B6: 236485500 | G6: Other | H6: 8904000
G7: White | H7: 170964000
G8: Grand Total | H8: 236485500

Sheet staff_master
A1: staff_id | B1: department | C1: grade | D1: contract_type | E1: fte | F1: start_date | G1: last_promotion_date | H1: gender | I1: ethnicity | J1: exit_date | K1: salary
A2: S00001 | B2: Sales | C2: G4 | D2: Fixed-term | E2: 1 | F2: 43745 | H2: Male | I2: White | J2: 44609 | K2: =_xlfn.XLOOKUP(C2,grade_salaries!A:A,grade_salaries!B:B) -> 28500
A3: S00002 | B3: IT Services | C3: G6 | D3: Permanent | E3: 1 | F3: 29/10/201GG3 | H3: Male | I3: White | K3: =_xlfn.XLOOKUP(C3,grade_salaries!A:A,grade_salaries!B:B) -> 42000
A4: S00003 | B4: Sales | C4: G4 | D4: Fixed-term | E4: 0.82 | F4: 40373 | H4: Female | I4: White | J4: GG31/0GG3/2018 | K4: =_xlfn.XLOOKUP(C4,grade_salaries!A:A,grade_salaries!B:B) -> 28500
A5: S00004 | B5: Customer Services | C5: G6 | D5: Permanent | E5: 1 | F5: 43286 | H5: Male | I5: Other | K5: =_xlfn.XLOOKUP(C5,grade_salaries!A:A,grade_salaries!B:B) -> 42000
A6: S00005 | B6: HR | C6: G4 | D6: Permanent | E6: 1 | F6: 41965 | G6: 43790 | H6: Female | I6: White | K6: =_xlfn.XLOOKUP(C6,grade_salaries!A:A,grade_salaries!B:B) -> 28500
A7: S00006 | B7: Legal and Governance | C7: G5 | D7: Permanent | E7: 0.41 | F7: 24/0GG3/2020 | H7: Female | I7: Mixed | K7: =_xlfn.XLOOKUP(C7,grade_salaries!A:A,grade_salaries!B:B) -> 33500
A8: S00007 | B8: Planning | C8: G3 | D8: Fixed-term | E8: 0.46 | F8: 44402 | H8: Female | I8: White | K8: =_xlfn.XLOOKUP(C8,grade_salaries!A:A,grade_salaries!B:B) -> 25000
A9: S00008 | B9: Customer Services | C9: G7 | D9: Permanent | E9: 1 | F9: 07/05/201GG3 | H9: Female | I9: White | K9: =_xlfn.XLOOKUP(C9,grade_salaries!A:A,grade_salaries!B:B) -> 51000
A10: S00009 | B10: Customer Services | C10: G9 | D10: Permanent | E10: 1 | F10: 42760 | H10: Female | I10: White | K10: =_xlfn.XLOOKUP(C10,grade_salaries!A:A,grade_salaries!B:B) -> 70000
A11: S00010 | B11: Customer Services | C11: G6 | D11: Permanent | E11: 1 | F11: 11/10/201GG3 | G11: 42653 | H11: Male | I11: White | K11: =_xlfn.XLOOKUP(C11,grade_salaries!A:A,grade_salaries!B:B) -> 42000
A12: S00011 | B12: Facilities | C12: G4 | D12: Permanent | E12: 1 | F12: 42504 | H12: Male | I12: White | K12: =_xlfn.XLOOKUP(C12,grade_salaries!A:A,grade_salaries!B:B) -> 28500
A13: S00012 | B13: Communications | C13: G5 | D13: Permanent | E13: 1 | F13: 24/0GG3/2015 | H13: Female | I13: White | K13: =_xlfn.XLOOKUP(C13,grade_salaries!A:A,grade_salaries!B:B) -> 33500
A14: S00013 | B14: HR | C14: G8 | D14: Permanent | E14: 1 | F14: 44719 | H14: Female | I14: White | K14: =_xlfn.XLOOKUP(C14,grade_salaries!A:A,grade_salaries!B:B) -> 63000
A15: S00014 | B15: Communications | C15: G8 | D15: Permanent | E15: 1 | F15: 40881 | H15: Female | I15: Asian | K15: =_xlfn.XLOOKUP(C15,grade_salaries!A:A,grade_salaries!B:B) -> 63000
A16: S00015 | B16: IT Services | C16: G6 | D16: Permanent | E16: 1 | F16: 41068 | H16: Male | I16: White | K16: =_xlfn.XLOOKUP(C16,grade_salaries!A:A,grade_salaries!B:B) -> 42000
A17: S00016 | B17: Sales | C17: G3 | D17: Permanent | E17: 1 | F17: 43402 | G17: 44497 | H17: Male | I17: White | K17: =_xlfn.XLOOKUP(C17,grade_salaries!A:A,grade_salaries!B:B) -> 25000
A18: S00017 | B18: Finance | C18: G5 | D18: Permanent | E18: 1 | F18: 40976 | H18: Male | I18: Black | K18: =_xlfn.XLOOKUP(C18,grade_salaries!A:A,grade_salaries!B:B) -> 33500
A19: S00018 | B19: Estates | C19: G3 | D19: Permanent | E19: 1 | F19: 42215 | H19: Female | I19: White | K19: =_xlfn.XLOOKUP(C19,grade_salaries!A:A,grade_salaries!B:B) -> 25000
A20: S00019 | B20: Estates | C20: G5 | D20: Fixed-term | E20: 1 | F20: 41372 | G20: 42832 | H20: Other | I20: White | K20: =_xlfn.XLOOKUP(C20,grade_salaries!A:A,grade_salaries!B:B) -> 33500
A21: S00020 | B21: Estates | C21: G7 | D21: Permanent | E21: 0.45 | F21: 40090 | H21: Female | I21: Mixed | K21: =_xlfn.XLOOKUP(C21,grade_salaries!A:A,grade_salaries!B:B) -> 51000
A22: S00021 | B22: IT Services | C22: G5 | D22: Permanent | E22: 1 | F22: 42204 | H22: Female | I22: White | K22: =_xlfn.XLOOKUP(C22,grade_salaries!A:A,grade_salaries!B:B) -> 33500
A23: S00022 | B23: Commercial Services | C23: G5 | D23: Fixed-term | E23: 1 | F23: 40695 | G23: 41790 | H23: Female | I23: Mixed | K23: =_xlfn.XLOOKUP(C23,grade_salaries!A:A,grade_salaries!B:B) -> 33500
A24: S00023 | B24: Marketing | C24: G7 | D24: Permanent | E24: 1 | F24: 45333 | H24: Female | I24: White | K24: =_xlfn.XLOOKUP(C24,grade_salaries!A:A,grade_salaries!B:B) -> 51000
A25: S00024 | B25: Security | C25: G6 | D25: Permanent | E25: 1 | F25: 39855 | H25: Male | I25: White | K25: =_xlfn.XLOOKUP(C25,grade_salaries!A:A,grade_salaries!B:B) -> 42000
A26: S00025 | B26: Procurement | C26: G5 | D26: Permanent | E26: 0.2 | F26: 43619 | H26: Male | I26: White | K26: =_xlfn.XLOOKUP(C26,grade_salaries!A:A,grade_salaries!B:B) -> 33500
A27: S00026 | B27: Finance | C27: G6 | D27: Permanent | E27: 1 | F27: 40722 | H27: Male | I27: White | K27: =_xlfn.XLOOKUP(C27,grade_salaries!A:A,grade_salaries!B:B) -> 42000
A28: S00027 | B28: Procurement | C28: G6 | D28: Fixed-term | E28: 0.23 | F28: 43470 | H28: Female | I28: Asian | K28: =_xlfn.XLOOKUP(C28,grade_salaries!A:A,grade_salaries!B:B) -> 42000
A29: S00028 | B29: Communications | C29: G7 | D29: Permanent | E29: 1 | F29: 41747 | H29: Male | I29: White | K29: =_xlfn.XLOOKUP(C29,grade_salaries!A:A,grade_salaries!B:B) -> 51000
A30: S00029 | B30: Communications | C30: G7 | D30: Permanent | E30: 1 | F30: 42511 | H30: Female | I30: White | J30: 43877 | K30: =_xlfn.XLOOKUP(C30,grade_salaries!A:A,grade_salaries!B:B) -> 51000
A31: S00030 | B31: Research and Development | C31: G5 | D31: Permanent | E31: 0.77 | F31: 40532 | H31: Female | I31: Asian | K31: =_xlfn.XLOOKUP(C31,grade_salaries!A:A,grade_salaries!B:B) -> 33500
A32: S00031 | B32: Sales | C32: G7 | D32: Permanent | E32: 1 | F32: 44745 | H32: Female | I32: White | K32: =_xlfn.XLOOKUP(C32,grade_salaries!A:A,grade_salaries!B:B) -> 51000
A33: S00032 | B33: Estates | C33: G6 | D33: Permanent | E33: 0.61 | F33: 45010 | H33: Male | I33: Black | K33: =_xlfn.XLOOKUP(C33,grade_salaries!A:A,grade_salaries!B:B) -> 42000
A34: S00033 | B34: Security | C34: G7 | D34: Fixed-term | E34: 0.86 | F34: 44698 | H34: Male | I34: White | J34: 45416 | K34: =_xlfn.XLOOKUP(C34,grade_salaries!A:A,grade_salaries!B:B) -> 51000
A35: S00034 | B35: Estates | C35: G4 | D35: Fixed-term | E35: 1 | F35: 41287 | H35: Female | I35: Asian | K35: =_xlfn.XLOOKUP(C35,grade_salaries!A:A,grade_salaries!B:B) -> 28500
A36: S00035 | B36: Customer Services | C36: G5 | D36: Permanent | E36: 0.25 | F36: 44731 | H36: Female | I36: Asian | K36: =_xlfn.XLOOKUP(C36,grade_salaries!A:A,grade_salaries!B:B) -> 33500
A37: S00036 | B37: Finance | C37: G5 | D37: Fixed-term | E37: 1 | F37: 41950 | G37: 43410 | H37: Male | I37: White | K37: =_xlfn.XLOOKUP(C37,grade_salaries!A:A,grade_salaries!B:B) -> 33500
A38: S00037 | B38: Security | C38: G6 | D38: Permanent | E38: 0.48 | F38: 44540 | H38: Male | I38: White | K38: =_xlfn.XLOOKUP(C38,grade_salaries!A:A,grade_salaries!B:B) -> 42000
A39: S00038 | B39: IT Services | C39: G8 | D39: Permanent | E39: 1 | F39: 43633 | H39: Male | I39: White | K39: =_xlfn.XLOOKUP(C39,grade_salaries!A:A,grade_salaries!B:B) -> 63000
A40: S00039 | B40: Facilities | C40: G7 | D40: Permanent | E40: 1 | F40: 41920 | H40: Female | I40: Mixed | K40: =_xlfn.XLOOKUP(C40,grade_salaries!A:A,grade_salaries!B:B) -> 51000
...

Sheet grade_salaries
A1: grade | B1: salary
A2: G3 | B2: 25000
A3: G4 | B3: 28500
A4: G5 | B4: 33500
A5: G6 | B5: 42000
A6: G7 | B6: 51000
A7: G8 | B7: 63000
A8: G9 | B8: 70000
